<robot>
  <link name="base_link"><!--Forma y tamano de la base movil-->
    <visual>
      <origin xyz="0 0 0.235" rpy="0 0 0"/><material name="blue"/>
      <geometry> <box size="0.42 0.42 0.20"/></geometry>
    </visual>
  </link>
  <link name="laser_link"><!--Forma y tamano del sensor laser-->
    <visual>
      <origin xyz="0 0 0" rpy="0 0 0"/><material name="black"/>
      <geometry> <box size="0.08 0.08 0.1"/></geometry>
    </visual>
  </link>
  <!-- Define la posicion del laser con respecto a la base movil-->
  <joint name="laser_connect" type="revolute">
    <origin xyz="0.17 0 0.44" rpy="0 0 0"/>
    <parent link="base_link"/><child link="laser_link"/>
    <axis xyz="1 0 0" />
    <dynamics damping ="0.1" />
    <limit effort="3.0" velocity="3.0" lower="-0.3" upper="1.5"/>
  </joint>
</robot>
